<?xml version="1.0" encoding="utf-8"?><testsuite errors="0" failures="5" name="pytest" skips="0" tests="26" time="49.534"><testcase classname="testmongodbaccess" file="testmongodbaccess.py" line="10" name="test_mongodbAcessOk" time="1.75348520279"></testcase><testcase classname="testmongodbaccess" file="testmongodbaccess.py" line="15" name="test_mongodbAcessFileError" time="0.000915765762329"><failure message="IOError: [Errno 2] No such file or directory: &apos;../test/config/configOkxx.json&apos;">def test_mongodbAcessFileError():
&gt;   	mongoDBAccessOk = MongoDBAccess(&quot;../test/config/configOkxx.json&quot;,&quot;DEBUG&quot;)

testmongodbaccess.py:17: 
_ _ _ _ _ _ _ _ _ _ _ _ _ _ _ _ _ _ _ _ _ _ _ _ _ _ _ _ _ _ _ _ _ _ _ _ _ _ _ _ _ _ _ _ _ _ _ _ _ _ _ _ _ _ _ _ _ _ _ _ _ _ _ _ _ _ _ _ _ _ _ _

self = &lt;pyproj.mongodbaccess.MongoDBAccess object at 0x7f8b68c47bd0&gt;, fileName = &apos;../test/config/configOkxx.json&apos;, levelLog = &apos;DEBUG&apos;

    def __init__(self, fileName, levelLog):
        &quot;&quot;&quot;Need a file where has got all parameters and level of Loggin&quot;&quot;&quot;
        self.logger = Logger(self.__class__.__name__, levelLog).get()
        self.logger.setLevel(&apos;INFO&apos;)
&gt;       config_text = open(fileName, &quot;r&quot;).read()
E       IOError: [Errno 2] No such file or directory: &apos;../test/config/configOkxx.json&apos;

../pyproj/mongodbaccess.py:20: IOError</failure></testcase><testcase classname="testmongodbaccess" file="testmongodbaccess.py" line="20" name="test_mongodbAcessError" time="1.72627997398"><system-err>mongodbaccess.py            42 ERROR    Authentication failure
</system-err></testcase><testcase classname="testmongodbaccess" file="testmongodbaccess.py" line="25" name="test_mongoDBAccess_find_oneOK" time="2.49438214302"></testcase><testcase classname="testmongodbaccess" file="testmongodbaccess.py" line="33" name="test_mongoDBAccess_find_oneErrorDB" time="2.08604383469"><system-err>mongodbaccess.py            42 ERROR    Authentication failure
mongodbaccess.py            94 ERROR    Database Not INIT Find
mongodbaccess.py            42 ERROR    Authentication failure
mongodbaccess.py            51 ERROR    Database Not INIT Find_one
mongodbaccess.py            42 ERROR    Authentication failure
mongodbaccess.py           121 ERROR    Database Not INIT Find
</system-err></testcase><testcase classname="testmongodbaccess" file="testmongodbaccess.py" line="41" name="test_mongoDBAccess_find_oneErrorCollection" time="2.50775289536"></testcase><testcase classname="testmongodbaccess" file="testmongodbaccess.py" line="49" name="test_mongoDBAccess_find_oneErrorFilter" time="2.4969329834"></testcase><testcase classname="testmongodbaccess" file="testmongodbaccess.py" line="57" name="test_mongoDBAccess_findOK" time="3.05956912041"><system-out>XXXXX
XXXXX
</system-out></testcase><testcase classname="testmongodbaccess" file="testmongodbaccess.py" line="71" name="test_mongoDBAccess_findErrorDB" time="1.52027082443"><system-err>mongodbaccess.py            42 ERROR    Authentication failure
mongodbaccess.py            63 ERROR    Database Not INIT Find
</system-err></testcase><testcase classname="testmongodbaccess" file="testmongodbaccess.py" line="77" name="test_mongoDBAccess_findErrorCollection" time="1.90528082848"></testcase><testcase classname="testmongodbaccess" file="testmongodbaccess.py" line="85" name="test_mongoDBAccess_findErrorFilter" time="2.49572896957"></testcase><testcase classname="testmongodbaccess" file="testmongodbaccess.py" line="97" name="test_mongoDBAccess_update_oneOK" time="3.07560396194"></testcase><testcase classname="testmongodbaccess" file="testmongodbaccess.py" line="110" name="test_mongoDBAccess_update_oneErrorDB" time="1.50678610802"><system-err>mongodbaccess.py            42 ERROR    Authentication failure
mongodbaccess.py            74 ERROR    Database Not INIT Update_one
</system-err></testcase><testcase classname="testmongodbaccess" file="testmongodbaccess.py" line="116" name="test_mongoDBAccess_update_oneErrorCollection" time="2.6468667984"></testcase><testcase classname="testmongodbaccess" file="testmongodbaccess.py" line="124" name="test_mongoDBAccess_update_oneErrorFind" time="2.70655608177"></testcase><testcase classname="testmongodbaccess" file="testmongodbaccess.py" line="132" name="test_mongoDBAccess_update_manyOK" time="3.10883903503"></testcase><testcase classname="testmongodbaccess" file="testmongodbaccess.py" line="152" name="test_mongoDBAccess_update_manyErrorDB" time="1.87705206871"><system-err>mongodbaccess.py            42 ERROR    Authentication failure
mongodbaccess.py            85 ERROR    Database Not INIT Update_one
</system-err></testcase><testcase classname="testmongodbaccess" file="testmongodbaccess.py" line="158" name="test_mongoDBAccess_update_manyErrorCollection" time="2.82939004898"></testcase><testcase classname="testmongodbaccess" file="testmongodbaccess.py" line="167" name="test_mongoDBAccess_update_manyErrorFind" time="2.50875067711"></testcase><testcase classname="testmongodbaccess" file="testmongodbaccess.py" line="177" name="test_mongoDBAccess_insertOK" time="3.0788898468"></testcase><testcase classname="testmongodbaccess" file="testmongodbaccess.py" line="192" name="test_mongoDBAccess_insertErrorDB" time="1.88809204102"><system-err>mongodbaccess.py            42 ERROR    Authentication failure
mongodbaccess.py            94 ERROR    Database Not INIT Find
</system-err></testcase><testcase classname="models.testblockdata" file="models/testblockdata.py" line="7" name="test_assert" time="0.000711917877197"></testcase><testcase classname="models.testmodelsgenerator" file="models/testmodelsgenerator.py" line="8" name="test_error_file_config" time="0.000919818878174"><failure message="IOError: [Errno 2] No such file or directory: &apos;config/configModelsxx.json&apos;">def test_error_file_config():
&gt;       models_generator = ModelsGenerator(&quot;config/configModelsxx.json&quot;, logging.DEBUG)

models/testmodelsgenerator.py:10: 
_ _ _ _ _ _ _ _ _ _ _ _ _ _ _ _ _ _ _ _ _ _ _ _ _ _ _ _ _ _ _ _ _ _ _ _ _ _ _ _ _ _ _ _ _ _ _ _ _ _ _ _ _ _ _ _ _ _ _ _ _ _ _ _ _ _ _ _ _ _ _ _

self = &lt;pyproj.models.modelsgenerator.ModelsGenerator object at 0x7f8b62371a50&gt;, fileConfig = &apos;config/configModelsxx.json&apos;, level_log = 10

    def __init__(self, fileConfig, level_log):
        self.logger = Logger(self.__class__.__name__, level_log).get()
&gt;       config_text = open(fileConfig, &quot;r&quot;).read()
E       IOError: [Errno 2] No such file or directory: &apos;config/configModelsxx.json&apos;

../pyproj/models/modelsgenerator.py:25: IOError</failure></testcase><testcase classname="models.testmodelsgenerator" file="models/testmodelsgenerator.py" line="12" name="test_generate_dataframe_error_path" time="0.482450962067"><failure message="assert None">def test_generate_dataframe_error_path():
        models_generator = ModelsGenerator(&quot;config/configModels.json&quot;, logging.DEBUG)
        result = models_generator.generate_dataframe(&quot;data/&quot;, &quot;dataframe.df&quot;)
&gt;       assert result
E       assert None

models/testmodelsgenerator.py:16: AssertionError</failure></testcase><testcase classname="models.testmodelsgenerator" file="models/testmodelsgenerator.py" line="17" name="test_generate_dataframe_without_matrix" time="0.477746009827"><failure message="assert None">def test_generate_dataframe_without_matrix():
        models_generator = ModelsGenerator(&quot;config/configModels.json&quot;, logging.DEBUG)
        result = models_generator.generate_dataframe(&quot;data/&quot;, &quot;dataframe.df&quot;)
&gt;       assert result
E       assert None

models/testmodelsgenerator.py:21: AssertionError</failure></testcase><testcase classname="models.testmodelsgenerator" file="models/testmodelsgenerator.py" line="22" name="test_generate_dataframe_with_matrix" time="0.465707302094"><failure message="assert None">def test_generate_dataframe_with_matrix():
        models_generator = ModelsGenerator(&quot;config/configModels.json&quot;, logging.DEBUG)
        result = models_generator.generate_dataframe(&quot;data/&quot;, &quot;dataframe.df&quot;,)
&gt;       assert result
E       assert None

models/testmodelsgenerator.py:26: AssertionError</failure></testcase></testsuite>